[2021-02-08 17:48:09] CRITICAL : Traceback (most recent call last):
  File "/root/bots/niansbot2/miraibot/__init__.py", line 141, in run
    get.bot().launch_blocking()
  File "/usr/local/lib/python3.8/dist-packages/graia/application/__init__.py", line 1546, in launch_blocking
    loop.run_until_complete(self.initialize())
  File "/usr/lib/python3.8/asyncio/base_events.py", line 616, in run_until_complete
    return future.result()
  File "/usr/local/lib/python3.8/dist-packages/graia/application/__init__.py", line 1436, in initialize
    await self.authenticate()
  File "/usr/local/lib/python3.8/dist-packages/graia/application/utilles.py", line 28, in wrapper
    return await func(self, *args, **kwargs)
  File "/usr/local/lib/python3.8/dist-packages/graia/application/__init__.py", line 309, in authenticate
    raise_for_return_code(data)
  File "/usr/local/lib/python3.8/dist-packages/graia/application/utilles.py", line 115, in raise_for_return_code
    raise exception_code
graia.application.exceptions.InvaildAuthkey

[2021-02-08 17:48:59] ERROR : Traceback (most recent call last):
  File "/usr/local/lib/python3.8/dist-packages/graia/broadcast/__init__.py", line 326, in Executor
    result = await run_always_await_safely(
  File "/usr/local/lib/python3.8/dist-packages/graia/broadcast/utilles.py", line 20, in run_always_await_safely
    return await callable(*args, **kwargs)
  File "/root/bots/niansbot2/plugins/McTool.py", line 19, in mc_tool
    async with aiohttp.request('get',f'https://api.bluesdawn.top/minecraft/server/api?host={hosts[group.id]}') as rest:
NameError: name 'hosts' is not defined

[2021-02-08 18:15:59] ERROR : 导入失败: ↓ 
Traceback (most recent call last):
  File "/root/bots/niansbot2/miraibot/plugin.py", line 41, in load_plugin
    module = importlib.import_module(module_name)
  File "/usr/lib/python3.8/importlib/__init__.py", line 127, in import_module
    return _bootstrap._gcd_import(name[level:], package, level)
  File "<frozen importlib._bootstrap>", line 1014, in _gcd_import
  File "<frozen importlib._bootstrap>", line 991, in _find_and_load
  File "<frozen importlib._bootstrap>", line 975, in _find_and_load_unlocked
  File "<frozen importlib._bootstrap>", line 671, in _load_unlocked
  File "<frozen importlib._bootstrap_external>", line 779, in exec_module
  File "<frozen importlib._bootstrap_external>", line 916, in get_code
  File "<frozen importlib._bootstrap_external>", line 846, in source_to_code
  File "<frozen importlib._bootstrap>", line 219, in _call_with_frames_removed
  File "/root/bots/niansbot2/plugins/McTool.py", line 26
    favicon = base64.decode(BytesIO(res["favicon"))
                                                 ^
SyntaxError: closing parenthesis ')' does not match opening parenthesis '['

[2021-02-08 18:17:10] ERROR : Traceback (most recent call last):
  File "/usr/local/lib/python3.8/dist-packages/graia/broadcast/__init__.py", line 326, in Executor
    result = await run_always_await_safely(
  File "/usr/local/lib/python3.8/dist-packages/graia/broadcast/utilles.py", line 20, in run_always_await_safely
    return await callable(*args, **kwargs)
  File "/root/bots/niansbot2/plugins/McTool.py", line 26, in mc_tool
    favicon = base64.decode(BytesIO(res["favicon"]))
TypeError: a bytes-like object is required, not 'str'

[2021-02-08 18:20:00] ERROR : Traceback (most recent call last):
  File "/usr/local/lib/python3.8/dist-packages/graia/broadcast/__init__.py", line 326, in Executor
    result = await run_always_await_safely(
  File "/usr/local/lib/python3.8/dist-packages/graia/broadcast/utilles.py", line 20, in run_always_await_safely
    return await callable(*args, **kwargs)
  File "/root/bots/niansbot2/plugins/McTool.py", line 25, in mc_tool
    favicon = base64.b64decode(res["favicon"])
  File "/usr/lib/python3.8/base64.py", line 87, in b64decode
    return binascii.a2b_base64(s)
binascii.Error: Invalid base64-encoded string: number of data characters (3741) cannot be 1 more than a multiple of 4

[2021-02-08 18:26:26] ERROR : Traceback (most recent call last):
  File "/usr/local/lib/python3.8/dist-packages/graia/broadcast/__init__.py", line 326, in Executor
    result = await run_always_await_safely(
  File "/usr/local/lib/python3.8/dist-packages/graia/broadcast/utilles.py", line 20, in run_always_await_safely
    return await callable(*args, **kwargs)
  File "/root/bots/niansbot2/plugins/McTool.py", line 25, in mc_tool
    favicon = base64.b64decode(res["favicon"].replace(r"data:image\\/png;base64,",""))
  File "/usr/lib/python3.8/base64.py", line 87, in b64decode
    return binascii.a2b_base64(s)
binascii.Error: Invalid base64-encoded string: number of data characters (3741) cannot be 1 more than a multiple of 4

[2021-02-08 18:29:20] ERROR : Traceback (most recent call last):
  File "/usr/local/lib/python3.8/dist-packages/graia/broadcast/__init__.py", line 326, in Executor
    result = await run_always_await_safely(
  File "/usr/local/lib/python3.8/dist-packages/graia/broadcast/utilles.py", line 20, in run_always_await_safely
    return await callable(*args, **kwargs)
  File "/root/bots/niansbot2/plugins/McTool.py", line 26, in mc_tool
    favicon = base64.b64decode(res["favicon"].replace(r"data:image\\/png;base64,",""))
  File "/usr/lib/python3.8/base64.py", line 87, in b64decode
    return binascii.a2b_base64(s)
binascii.Error: Invalid base64-encoded string: number of data characters (3741) cannot be 1 more than a multiple of 4

[2021-02-08 18:32:58] ERROR : Traceback (most recent call last):
  File "/usr/local/lib/python3.8/dist-packages/graia/broadcast/__init__.py", line 326, in Executor
    result = await run_always_await_safely(
  File "/usr/local/lib/python3.8/dist-packages/graia/broadcast/utilles.py", line 20, in run_always_await_safely
    return await callable(*args, **kwargs)
  File "/root/bots/niansbot2/plugins/McTool.py", line 27, in mc_tool
    favicon = base64.b64decode(res["favicon"].replace(r"data:image\\/png;base64,",""))
  File "/usr/lib/python3.8/base64.py", line 87, in b64decode
    return binascii.a2b_base64(s)
binascii.Error: Invalid base64-encoded string: number of data characters (3741) cannot be 1 more than a multiple of 4

[2021-02-08 18:39:56] ERROR : Traceback (most recent call last):
  File "/usr/local/lib/python3.8/dist-packages/graia/broadcast/__init__.py", line 326, in Executor
    result = await run_always_await_safely(
  File "/usr/local/lib/python3.8/dist-packages/graia/broadcast/utilles.py", line 20, in run_always_await_safely
    return await callable(*args, **kwargs)
  File "/root/bots/niansbot2/plugins/McTool.py", line 26, in mc_tool
    code = res["favicon"].decode("utf-8")
AttributeError: 'str' object has no attribute 'decode'

[2021-02-08 18:45:38] ERROR : Traceback (most recent call last):
  File "/usr/local/lib/python3.8/dist-packages/graia/broadcast/__init__.py", line 326, in Executor
    result = await run_always_await_safely(
  File "/usr/local/lib/python3.8/dist-packages/graia/broadcast/utilles.py", line 20, in run_always_await_safely
    return await callable(*args, **kwargs)
  File "/root/bots/niansbot2/plugins/McTool.py", line 27, in mc_tool
    favicon = base64.b64decode(code.replace(r"data:image\\/png;base64,",""))
TypeError: a bytes-like object is required, not 'str'

[2021-02-08 18:47:39] ERROR : Traceback (most recent call last):
  File "/usr/local/lib/python3.8/dist-packages/graia/broadcast/__init__.py", line 326, in Executor
    result = await run_always_await_safely(
  File "/usr/local/lib/python3.8/dist-packages/graia/broadcast/utilles.py", line 20, in run_always_await_safely
    return await callable(*args, **kwargs)
  File "/root/bots/niansbot2/plugins/McTool.py", line 27, in mc_tool
    favicon = base64.b64decode(bytes(code.replace(r"data:image\\/png;base64,","")))
TypeError: a bytes-like object is required, not 'str'

[2021-02-08 18:49:23] ERROR : 导入失败: ↓ 
Traceback (most recent call last):
  File "/root/bots/niansbot2/miraibot/plugin.py", line 41, in load_plugin
    module = importlib.import_module(module_name)
  File "/usr/lib/python3.8/importlib/__init__.py", line 127, in import_module
    return _bootstrap._gcd_import(name[level:], package, level)
  File "<frozen importlib._bootstrap>", line 1014, in _gcd_import
  File "<frozen importlib._bootstrap>", line 991, in _find_and_load
  File "<frozen importlib._bootstrap>", line 975, in _find_and_load_unlocked
  File "<frozen importlib._bootstrap>", line 671, in _load_unlocked
  File "<frozen importlib._bootstrap_external>", line 779, in exec_module
  File "<frozen importlib._bootstrap_external>", line 916, in get_code
  File "<frozen importlib._bootstrap_external>", line 846, in source_to_code
  File "<frozen importlib._bootstrap>", line 219, in _call_with_frames_removed
  File "/root/bots/niansbot2/plugins/McTool.py", line 28
    async with aiofiles.open("fav.png",mode="wb") as f:
          ^
SyntaxError: invalid syntax

[2021-02-08 18:51:29] ERROR : 导入失败: ↓ 
Traceback (most recent call last):
  File "/root/bots/niansbot2/miraibot/plugin.py", line 41, in load_plugin
    module = importlib.import_module(module_name)
  File "/usr/lib/python3.8/importlib/__init__.py", line 127, in import_module
    return _bootstrap._gcd_import(name[level:], package, level)
  File "<frozen importlib._bootstrap>", line 1014, in _gcd_import
  File "<frozen importlib._bootstrap>", line 991, in _find_and_load
  File "<frozen importlib._bootstrap>", line 975, in _find_and_load_unlocked
  File "<frozen importlib._bootstrap>", line 671, in _load_unlocked
  File "<frozen importlib._bootstrap_external>", line 779, in exec_module
  File "<frozen importlib._bootstrap_external>", line 916, in get_code
  File "<frozen importlib._bootstrap_external>", line 846, in source_to_code
  File "<frozen importlib._bootstrap>", line 219, in _call_with_frames_removed
  File "/root/bots/niansbot2/plugins/McTool.py", line 28
    async with aiofiles.open("fav.png",mode="wb") as f:
          ^
SyntaxError: invalid syntax

[2021-02-08 18:55:05] ERROR : Traceback (most recent call last):
  File "/usr/local/lib/python3.8/dist-packages/graia/broadcast/__init__.py", line 326, in Executor
    result = await run_always_await_safely(
  File "/usr/local/lib/python3.8/dist-packages/graia/broadcast/utilles.py", line 20, in run_always_await_safely
    return await callable(*args, **kwargs)
  File "/root/bots/niansbot2/plugins/McTool.py", line 27, in mc_tool
    favicon = base64.b64decode((code.replace(r"data:image\\/png;base64,","")))
  File "/usr/lib/python3.8/base64.py", line 87, in b64decode
    return binascii.a2b_base64(s)
binascii.Error: Invalid base64-encoded string: number of data characters (3741) cannot be 1 more than a multiple of 4

[2021-02-08 18:55:45] ERROR : Traceback (most recent call last):
  File "/usr/local/lib/python3.8/dist-packages/graia/broadcast/__init__.py", line 326, in Executor
    result = await run_always_await_safely(
  File "/usr/local/lib/python3.8/dist-packages/graia/broadcast/utilles.py", line 20, in run_always_await_safely
    return await callable(*args, **kwargs)
  File "/root/bots/niansbot2/plugins/McTool.py", line 28, in mc_tool
    favicon = base64.b64decode((code.replace(r"data:image\\/png;base64,","")))
  File "/usr/lib/python3.8/base64.py", line 87, in b64decode
    return binascii.a2b_base64(s)
binascii.Error: Invalid base64-encoded string: number of data characters (3741) cannot be 1 more than a multiple of 4

[2021-02-08 19:02:25] ERROR : 导入失败: ↓ 
Traceback (most recent call last):
  File "/root/bots/niansbot2/miraibot/plugin.py", line 41, in load_plugin
    module = importlib.import_module(module_name)
  File "/usr/lib/python3.8/importlib/__init__.py", line 127, in import_module
    return _bootstrap._gcd_import(name[level:], package, level)
  File "<frozen importlib._bootstrap>", line 1014, in _gcd_import
  File "<frozen importlib._bootstrap>", line 991, in _find_and_load
  File "<frozen importlib._bootstrap>", line 975, in _find_and_load_unlocked
  File "<frozen importlib._bootstrap>", line 671, in _load_unlocked
  File "<frozen importlib._bootstrap_external>", line 779, in exec_module
  File "<frozen importlib._bootstrap_external>", line 916, in get_code
  File "<frozen importlib._bootstrap_external>", line 846, in source_to_code
  File "<frozen importlib._bootstrap>", line 219, in _call_with_frames_removed
  File "/root/bots/niansbot2/plugins/McTool.py", line 30
    result = f"服务器查询:\n状态:{res['status']}\n{res['version']['version']"
             ^
SyntaxError: f-string: expecting '}'

[2021-02-08 19:07:04] ERROR : Traceback (most recent call last):
  File "/usr/local/lib/python3.8/dist-packages/graia/broadcast/__init__.py", line 326, in Executor
    result = await run_always_await_safely(
  File "/usr/local/lib/python3.8/dist-packages/graia/broadcast/utilles.py", line 20, in run_always_await_safely
    return await callable(*args, **kwargs)
  File "/root/bots/niansbot2/plugins/McTool.py", line 30, in mc_tool
    result = f"服务器查询:\n状态:{res['status']}\n{res['version']['version']}\n在线玩家:{['players']['list']['name']}"
TypeError: list indices must be integers or slices, not str

[2021-02-08 19:11:33] ERROR : Traceback (most recent call last):
  File "/usr/local/lib/python3.8/dist-packages/graia/broadcast/__init__.py", line 326, in Executor
    result = await run_always_await_safely(
  File "/usr/local/lib/python3.8/dist-packages/graia/broadcast/utilles.py", line 20, in run_always_await_safely
    return await callable(*args, **kwargs)
  File "/root/bots/niansbot2/plugins/McTool.py", line 28, in mc_tool
    for i in ['players']['list']:
TypeError: list indices must be integers or slices, not str

[2021-02-08 19:12:47] ERROR : Traceback (most recent call last):
  File "/usr/local/lib/python3.8/dist-packages/graia/broadcast/__init__.py", line 326, in Executor
    result = await run_always_await_safely(
  File "/usr/local/lib/python3.8/dist-packages/graia/broadcast/utilles.py", line 20, in run_always_await_safely
    return await callable(*args, **kwargs)
  File "/root/bots/niansbot2/plugins/McTool.py", line 29, in mc_tool
    players = players+"\n{i['name']}"
UnboundLocalError: local variable 'players' referenced before assignment

[2021-02-08 19:14:00] ERROR : 导入失败: ↓ 
Traceback (most recent call last):
  File "/root/bots/niansbot2/miraibot/plugin.py", line 41, in load_plugin
    module = importlib.import_module(module_name)
  File "/usr/lib/python3.8/importlib/__init__.py", line 127, in import_module
    return _bootstrap._gcd_import(name[level:], package, level)
  File "<frozen importlib._bootstrap>", line 1014, in _gcd_import
  File "<frozen importlib._bootstrap>", line 991, in _find_and_load
  File "<frozen importlib._bootstrap>", line 975, in _find_and_load_unlocked
  File "<frozen importlib._bootstrap>", line 671, in _load_unlocked
  File "<frozen importlib._bootstrap_external>", line 779, in exec_module
  File "<frozen importlib._bootstrap_external>", line 916, in get_code
  File "<frozen importlib._bootstrap_external>", line 846, in source_to_code
  File "<frozen importlib._bootstrap>", line 219, in _call_with_frames_removed
  File "/root/bots/niansbot2/plugins/McTool.py", line 29
    global players = players+"\n{i['name']}"
                   ^
SyntaxError: invalid syntax

[2021-02-08 19:14:23] ERROR : 导入失败: ↓ 
Traceback (most recent call last):
  File "/root/bots/niansbot2/miraibot/plugin.py", line 41, in load_plugin
    module = importlib.import_module(module_name)
  File "/usr/lib/python3.8/importlib/__init__.py", line 127, in import_module
    return _bootstrap._gcd_import(name[level:], package, level)
  File "<frozen importlib._bootstrap>", line 1014, in _gcd_import
  File "<frozen importlib._bootstrap>", line 991, in _find_and_load
  File "<frozen importlib._bootstrap>", line 975, in _find_and_load_unlocked
  File "<frozen importlib._bootstrap>", line 671, in _load_unlocked
  File "<frozen importlib._bootstrap_external>", line 779, in exec_module
  File "<frozen importlib._bootstrap_external>", line 916, in get_code
  File "<frozen importlib._bootstrap_external>", line 846, in source_to_code
  File "<frozen importlib._bootstrap>", line 219, in _call_with_frames_removed
  File "/root/bots/niansbot2/plugins/McTool.py", line 29
    global players = players+"\n{i['name']}"
                   ^
SyntaxError: invalid syntax

[2021-02-08 19:18:14] ERROR : Traceback (most recent call last):
  File "/usr/local/lib/python3.8/dist-packages/graia/broadcast/__init__.py", line 326, in Executor
    result = await run_always_await_safely(
  File "/usr/local/lib/python3.8/dist-packages/graia/broadcast/utilles.py", line 20, in run_always_await_safely
    return await callable(*args, **kwargs)
  File "/root/bots/niansbot2/plugins/McTool.py", line 30, in mc_tool
    players = players+f"\n{i['name']}"
TypeError: string indices must be integers

[2021-02-08 19:59:31] ERROR : Traceback (most recent call last):
  File "/usr/local/lib/python3.8/dist-packages/graia/broadcast/__init__.py", line 326, in Executor
    result = await run_always_await_safely(
  File "/usr/local/lib/python3.8/dist-packages/graia/broadcast/utilles.py", line 20, in run_always_await_safely
    return await callable(*args, **kwargs)
  File "/root/bots/niansbot2/plugins/McTool.py", line 26, in mc_tool
    code = res["favicon"]
KeyError: 'favicon'

[2021-02-08 20:04:52] ERROR : Traceback (most recent call last):
  File "/usr/local/lib/python3.8/dist-packages/graia/broadcast/__init__.py", line 326, in Executor
    result = await run_always_await_safely(
  File "/usr/local/lib/python3.8/dist-packages/graia/broadcast/utilles.py", line 20, in run_always_await_safely
    return await callable(*args, **kwargs)
  File "/root/bots/niansbot2/plugins/McTool.py", line 26, in mc_tool
    code = res["favicon"]
KeyError: 'favicon'

[2021-02-09 07:43:59] ERROR : Traceback (most recent call last):
  File "/usr/local/lib/python3.8/dist-packages/graia/broadcast/__init__.py", line 326, in Executor
    result = await run_always_await_safely(
  File "/usr/local/lib/python3.8/dist-packages/graia/broadcast/utilles.py", line 20, in run_always_await_safely
    return await callable(*args, **kwargs)
  File "/root/bots/niansbot2/plugins/McTool.py", line 29, in mc_tool
    for i in res['players']['list']:
TypeError: 'NoneType' object is not iterable

[2021-02-09 08:33:18] ERROR : Traceback (most recent call last):
  File "/usr/local/lib/python3.8/dist-packages/graia/broadcast/__init__.py", line 326, in Executor
    result = await run_always_await_safely(
  File "/usr/local/lib/python3.8/dist-packages/graia/broadcast/utilles.py", line 20, in run_always_await_safely
    return await callable(*args, **kwargs)
  File "/root/bots/niansbot2/plugins/McTool.py", line 29, in mc_tool
    for i in res['players']['list']:
TypeError: 'NoneType' object is not iterable

[2021-02-09 08:33:29] ERROR : Traceback (most recent call last):
  File "/usr/local/lib/python3.8/dist-packages/graia/broadcast/__init__.py", line 326, in Executor
    result = await run_always_await_safely(
  File "/usr/local/lib/python3.8/dist-packages/graia/broadcast/utilles.py", line 20, in run_always_await_safely
    return await callable(*args, **kwargs)
  File "/root/bots/niansbot2/plugins/McTool.py", line 29, in mc_tool
    for i in res['players']['list']:
TypeError: 'NoneType' object is not iterable

[2021-02-09 08:34:24] ERROR : Traceback (most recent call last):
  File "/usr/local/lib/python3.8/dist-packages/graia/broadcast/__init__.py", line 326, in Executor
    result = await run_always_await_safely(
  File "/usr/local/lib/python3.8/dist-packages/graia/broadcast/utilles.py", line 20, in run_always_await_safely
    return await callable(*args, **kwargs)
  File "/root/bots/niansbot2/plugins/McTool.py", line 29, in mc_tool
    for i in res['players']['list']:
TypeError: 'NoneType' object is not iterable

[2021-02-09 10:04:58] ERROR : Traceback (most recent call last):
  File "/usr/local/lib/python3.8/dist-packages/graia/broadcast/__init__.py", line 326, in Executor
    result = await run_always_await_safely(
  File "/usr/local/lib/python3.8/dist-packages/graia/broadcast/utilles.py", line 20, in run_always_await_safely
    return await callable(*args, **kwargs)
  File "/root/bots/niansbot2/plugins/McTool.py", line 29, in mc_tool
    for i in res['players']['list']:
TypeError: 'NoneType' object is not iterable

[2021-02-09 10:05:11] ERROR : Traceback (most recent call last):
  File "/usr/local/lib/python3.8/dist-packages/graia/broadcast/__init__.py", line 326, in Executor
    result = await run_always_await_safely(
  File "/usr/local/lib/python3.8/dist-packages/graia/broadcast/utilles.py", line 20, in run_always_await_safely
    return await callable(*args, **kwargs)
  File "/root/bots/niansbot2/plugins/McTool.py", line 29, in mc_tool
    for i in res['players']['list']:
TypeError: 'NoneType' object is not iterable

[2021-02-09 14:17:38] ERROR : Traceback (most recent call last):
  File "/usr/local/lib/python3.8/dist-packages/graia/broadcast/__init__.py", line 326, in Executor
    result = await run_always_await_safely(
  File "/usr/local/lib/python3.8/dist-packages/graia/broadcast/utilles.py", line 20, in run_always_await_safely
    return await callable(*args, **kwargs)
  File "/root/bots/niansbot2/plugins/McTool.py", line 29, in mc_tool
    for i in res['players']['list']:
TypeError: 'NoneType' object is not iterable

[2021-02-09 14:18:06] ERROR : Traceback (most recent call last):
  File "/usr/local/lib/python3.8/dist-packages/graia/broadcast/__init__.py", line 326, in Executor
    result = await run_always_await_safely(
  File "/usr/local/lib/python3.8/dist-packages/graia/broadcast/utilles.py", line 20, in run_always_await_safely
    return await callable(*args, **kwargs)
  File "/root/bots/niansbot2/plugins/McTool.py", line 29, in mc_tool
    for i in res['players']['list']:
TypeError: 'NoneType' object is not iterable

[2021-02-09 14:19:51] ERROR : Traceback (most recent call last):
  File "/usr/local/lib/python3.8/dist-packages/graia/broadcast/__init__.py", line 326, in Executor
    result = await run_always_await_safely(
  File "/usr/local/lib/python3.8/dist-packages/graia/broadcast/utilles.py", line 20, in run_always_await_safely
    return await callable(*args, **kwargs)
  File "/root/bots/niansbot2/plugins/McTool.py", line 29, in mc_tool
    for i in res['players']['list']:
TypeError: 'NoneType' object is not iterable

[2021-02-09 14:20:36] ERROR : Traceback (most recent call last):
  File "/usr/local/lib/python3.8/dist-packages/graia/broadcast/__init__.py", line 326, in Executor
    result = await run_always_await_safely(
  File "/usr/local/lib/python3.8/dist-packages/graia/broadcast/utilles.py", line 20, in run_always_await_safely
    return await callable(*args, **kwargs)
  File "/root/bots/niansbot2/plugins/McTool.py", line 29, in mc_tool
    for i in res['players']['list']:
TypeError: 'NoneType' object is not iterable

